<mujoco model="kangaroo_hands">
  <compiler angle="radian" meshdir="assets" autolimits="true"/>

  <option timestep="0.001" iterations="1" ls_iterations="5">
    <flag eulerdamp="disable"/>
  </option>

  <size nkey="1"/>

  <statistic meansize="0.04" extent="1.8" center="0 0 1"/>

  <default>
    <joint limited="true" armature="0.1" damping="10" frictionloss="1"/>
    <site size="0.01 0.005 0.005" group="5" rgba="1 0 0 1"/>
    <default class="visual">
        <geom type="mesh" contype="0" conaffinity="0" group="1" density="0"/>
    </default>
    <default class="collision">
        <geom type="capsule" group="3" material="bright_orange"/>
    </default>
  </default>

  <asset>
    <!-- world assets -->
    <texture type="skybox" colorspace="auto" builtin="gradient" rgb1="0.3 0.5 0.7" rgb2="0 0 0" width="512" height="3072"/>
    <texture type="2d" colorspace="auto" name="groundplane" builtin="checker" mark="edge" rgb1="0.2 0.3 0.4" rgb2="0.1 0.2 0.3" markrgb="0.8 0.8 0.8" width="300" height="300"/>
    <!-- robot assets -->
    <material name="dark_gray" rgba="0.298039 0.298039 0.298039 1"/>
    <material name="bright_orange" rgba="1 0.65 0 0.2"/>
    <mesh name="base_link_with_pelvis" content_type="model/stl"           file="base/base_link_with_pelvis.stl" />
    <mesh name="handle" content_type="model/stl"                          file="base/handle.stl" />
    <mesh name="pelvis_base_link" content_type="model/stl"                file="pelvis/pelvis_base_link.stl" />    <mesh name="pelvis_1_link" content_type="model/stl"                   file="pelvis/pelvis_1_link.stl" />    <mesh name="pelvis_2_link" content_type="model/stl"                   file="pelvis/pelvis_2_link.stl" />    <mesh name="torso_link" content_type="model/stl"                      file="torso/torso_link.stl" />    <mesh name="leg_left_1_link" content_type="model/stl"                 file="leg/leg_left_1_link.stl" />
    <mesh name="leg_left_2_link" content_type="model/stl"                 file="leg/leg_left_2_link.stl" />
    <mesh name="leg_left_3_link" content_type="model/stl"                 file="leg/leg_left_3_link.stl" />
    <mesh name="leg_femur_link" content_type="model/stl"                  file="leg/leg_femur_link.stl" />    <mesh name="leg_tibia_link" content_type="model/stl"                  file="leg/leg_tibia_link.stl" />    <mesh name="leg_6_link" content_type="model/stl"                      file="leg/leg_6_link.stl" />
    <mesh name="leg_7_link" content_type="model/stl"                      file="leg/leg_7_link.stl" />
    <mesh name="leg_right_1_link" content_type="model/stl"                file="leg/leg_right_1_link.stl" />
    <mesh name="leg_right_2_link" content_type="model/stl"                file="leg/leg_right_2_link.stl" />
    <mesh name="leg_right_3_link" content_type="model/stl"                file="leg/leg_right_3_link.stl" />    <mesh name="leg_6_link1" content_type="model/stl"                     file="leg/leg_6_link.stl" scale="1 -1 1" />
    <mesh name="leg_7_link1" content_type="model/stl"                     file="leg/leg_7_link.stl" scale="1 -1 1" />
    <mesh name="arm_base_link" content_type="model/stl"                   file="arm_7dof/arm_base_link.STL" />
    <mesh name="arm1_link" content_type="model/stl"                       file="arm_7dof/arm1_link.STL" />
    <mesh name="arm2_link" content_type="model/stl"                       file="arm_7dof/arm2_link.STL" />
    <mesh name="arm3_link" content_type="model/stl"                       file="arm_7dof/arm3_link.STL" />
    <mesh name="arm4_link" content_type="model/stl"                       file="arm_7dof/arm4_link.STL" />
    <mesh name="arm5_tip_link" content_type="model/stl"                   file="arm_7dof/arm5_tip_link.STL" />
    <mesh name="seedRobotics_adaptor" content_type="model/stl"            file="rh8d/seedRobotics_adaptor.STL" />
    <mesh name="forearm_link" content_type="model/stl"                    file="rh8d/forearm_link.STL" />
    <mesh name="wrist_link" content_type="model/stl"                      file="rh8d/wrist_link.STL" />
    <mesh name="palm_left_link" content_type="model/stl"                  file="rh8d/palm_left_link.STL" />
    <mesh name="phalanx_link" content_type="model/stl"                    file="rh8d/phalanx_link.STL" />
    <mesh name="tip_link" content_type="model/stl"                        file="rh8d/tip_link.STL" />
    <mesh name="thumb_left_link" content_type="model/stl"                 file="rh8d/thumb_left_link.STL" />
    <mesh name="thumb_phalanx_link" content_type="model/stl"              file="rh8d/thumb_phalanx_link.STL" />
    <mesh name="palm_right_link" content_type="model/stl"                 file="rh8d/palm_right_link.STL" />
    <mesh name="thumb_right_link" content_type="model/stl"                file="rh8d/thumb_right_link.STL" />
  </asset>


  <worldbody>
    <!-- <geom name="floor" size="0 0 0.05" type="plane" material="groundplane"/>
    <light name="spotlight" target="base_link" pos="1 0 20" dir="0 0 -1" mode="targetbody"/> -->
    <body name="base_link" pos="0 0 1.2">
      <inertial pos="-0.0913441 -0.0313598 0.00676412" quat="0.445077 0.406142 -0.397876 0.691845" mass="4.82254" diaginertia="0.0600103 0.0509711 0.0269078" />
      <joint name="origin" type="free" />
      <geom class="visual" mesh="base_link_with_pelvis" />
      <geom class="visual" mesh="handle" />
      <geom pos="-0.0918 0 -0.0455" quat="1 0 0 0" class="visual" mesh="pelvis_base_link" />
      <!-- <geom size="0.0588148 0.0758545" pos="-0.105334 -2.0459e-05 -0.0039883" quat="0.690602 0.00028847 0.723235 -1.36639e-06" class="collision"/> -->
      <body name="pelvis_1_link" pos="-0.0918 0 0.0065" quat="0.707105 0 0.707108 0">
        <inertial pos="-0.02593 -1e-06 0.001466" quat="0.99984 0 -0.0179004 0" mass="1.24856" diaginertia="0.00539676 0.004808 0.00324424" />
        <joint name="pelvis_1_joint" axis="0 0 -1" range="-0.349066 0.349066"/>
        <geom class="visual" mesh="pelvis_1_link" />
        <body name="pelvis_2_link" pos="-0.0591 0 0" quat="0.707105 0 -0.707108 0">
          <site name="imu" pos="0.071 -0.0014 0.0261" quat="0 -0.707107 0.707107 0"/>
          <inertial pos="-0.0096298 -0.000857135 0.220739" quat="0.999875 0.0105643 0.00161433 -0.0116448" mass="13.7723" diaginertia="0.312791 0.291456 0.113386" />
          <joint name="pelvis_2_joint" axis="0 0 -1" range="-1.309 1.309"/>
          <geom class="visual" mesh="pelvis_2_link" />
          <geom pos="0 0 0.0061" quat="1 0 0 0" class="visual" mesh="torso_link" />
          <geom name="pelvis_2_collision" size="0.163724 0.162985" pos="4.77798e-07 -1.67441e-06 0.234507" quat="1 -3.97075e-06 -1.19191e-05 0" class="collision"/>
          <geom pos="0 0.105954 0.390496" quat="0.642802 -0.766033 1.86923e-06 1.63502e-07" class="visual" mesh="arm_base_link" />
          <geom pos="0 -0.105954 0.390496" quat="1.01637e-06 8.52866e-07 0.766033 -0.642802" class="visual" mesh="arm_base_link" />
          <body name="arm_left_1_link" pos="0 0.105954 0.390496" quat="-4.68302e-06 -2.52466e-06 0.642799 -0.766035">
            <inertial pos="0.0070639 0.0030301 -0.05724" quat="0.991252 0.0809813 -0.0910271 0.0507521" mass="1.1788" diaginertia="0.00192068 0.00177268 0.000875278" />
            <joint name="arm_left_1_joint" axis="0 0 -1" range="-2.61799 2.61799"/>
            <geom class="visual" mesh="arm1_link" />
            <!-- <geom size="0.0486559 0.0706888" pos="-0.0112961 -0.00871686 -0.0875926" quat="0.993843 -0.0674454 0.087908 1.78949e-08" class="collision"/> -->
            <body name="arm_left_2_link" pos="0.03711 0.02 -0.17011" quat="0.707105 0 0.707108 0">
              <inertial pos="0.029543 -0.0049762 -0.03224" quat="0.0848392 0.690549 -0.0139433 0.718157" mass="1.2955" diaginertia="0.00278545 0.00260446 0.00100708" />
              <joint name="arm_left_2_joint" range="-1.13446 2.44346"/>
              <geom class="visual" mesh="arm2_link" />
              <geom name="arm_left_2_collision" size="0.0645032 0.0664882" pos="-0.0638385 0.00999977 -0.0388" quat="0.659371 0.116779 0.742693 -1.43134e-06" class="collision"/>
              <body name="arm_left_3_link" pos="0.15989 -0.02 -0.03711" quat="0.707105 0 -0.707108 0">
                <inertial pos="-0.00706385 -0.00303013 -0.0572396" quat="0.991251 -0.0809737 0.0910312 0.0507756" mass="1.17879" diaginertia="0.00192065 0.00177272 0.000875276" />
                <joint name="arm_left_3_joint" axis="0 0 -1" range="-2.61799 2.61799"/>
                <geom class="visual" mesh="arm3_link" />
                <!-- <geom size="0.0661152 0.0583363" pos="0.00922975 0.00265488 -0.0826432" quat="0.180736 -0.514963 0.837942 5.70431e-07" class="collision"/> -->
                <body name="arm_left_4_link" pos="-0.03711 -0.02 -0.17011" quat="0.707105 0 -0.707108 0">
                  <inertial pos="-0.0666639 0.0102985 -0.0351108" quat="0.0552758 0.727273 -0.0700841 0.68052" mass="1.80676" diaginertia="0.00263554 0.00245424 0.00145523" />
                  <joint name="arm_left_4_joint" range="-1.13446 2.44346"/>
                  <geom class="visual" mesh="arm4_link" />
                  <geom name="arm_left_4_collision" size="0.054849 0.219217" pos="0.210246 -0.0167497 -0.0171982" quat="0.733112 0.0532001 0.678025 -2.2842e-07" class="collision"/>
                  <body name="arm_left_5_link" pos="-0.17011 0.02 -0.03711" quat="0.707105 0 -0.707108 0">
                    <inertial pos="0.00582226 -0.000330137 0.0702339" quat="0.965441 -0.00213396 -0.0211456 0.259754" mass="0.73786" diaginertia="0.00302019 0.00300619 0.000658945" />
                    <joint name="arm_left_5_joint" axis="0 0 -1" range="-1.57 1.57"/>
                    <geom class="visual" mesh="arm5_tip_link" />
                    <!-- <site name="ee_left" pos="0.0 0.0 0.0"/> -->
                    <geom pos="0 0 0.0303" quat="-0.707107 0 0 0.707106" class="visual" mesh="seedRobotics_adaptor" />
                    <geom pos="0 0 0.0498" quat="-0.000398673 0 0 1" class="visual" mesh="forearm_link" />
                    <body name="hand_left_palm_base_link" pos="0 0 0.2158" quat="0.707108 -0.000282842 0.707105 0.000282843">
                      <inertial pos="0.00858508 -2.4614e-09 0.000249999" quat="0.5 0.5 -0.5 0.5" mass="0.0509809" diaginertia="1.88432e-05 1.37535e-05 9.79678e-06" />
                      <joint name="hand_left_palm_roll_joint" axis="0 0 -1" range="-0.785398 0.785398"/>
                      <geom class="visual" mesh="wrist_link" />
                      <body name="hand_left_palm_link" quat="0.707105 -0.707108 0 0">
                        <site name="ee_left" pos="0.0 0.0 0.0"/>
                        <inertial pos="-0.052625 0.000781495 -0.00275893" quat="0.740136 -0.0434134 -7.69336e-05 0.671055" mass="0.0389736" diaginertia="2.76787e-05 1.98299e-05 1.10229e-05" />
                        <joint name="hand_left_palm_pitch_joint" range="-0.785398 0.785398"/>
                        <geom class="visual" mesh="palm_left_link" />
                        <body name="hand_left_index_prox_link" pos="-0.081291 -0.0045543 -0.036786" quat="0.991128 -0.0829563 -0.0508768 0.0905266">
                          <inertial pos="-0.0111483 9.28713e-05 -6.08808e-05" quat="0.509105 0.509044 0.490967 0.490548" mass="0.00478125" diaginertia="4.07603e-07 3.57283e-07 1.57379e-07" />
                          <joint name="hand_left_index_prox_joint" range="0 1.5708"/>
                          <geom class="visual" mesh="phalanx_link" />
                          <body name="hand_left_index_mid_link" pos="-0.0258748 0 0">
                            <inertial pos="-0.0111483 9.28713e-05 -6.08808e-05" quat="0.509105 0.509044 0.490967 0.490548" mass="0.00478125" diaginertia="4.07603e-07 3.57283e-07 1.57379e-07" />
                            <joint name="hand_left_index_mid_joint" range="0 1.5708"/>
                            <geom class="visual" mesh="phalanx_link" />
                            <body name="hand_left_index_dist_link" pos="-0.0258748 0 0">
                              <inertial pos="-0.01044 -0.00064 -6e-05" quat="0.48992 0.51041 0.454557 0.541145" mass="0.00476" diaginertia="4.20832e-07 3.33472e-07 2.4112e-07" />
                              <joint name="hand_left_index_dist_joint" range="0 1.5708"/>
                              <geom class="visual" mesh="tip_link" />
                            </body>
                          </body>
                        </body>
                        <body name="hand_left_middle_prox_link" pos="-0.082896 -0.0014507 -0.011829" quat="0.995247 -0.0434532 -0.0038016 0.0870713">
                          <inertial pos="-0.0111483 9.28713e-05 -6.08808e-05" quat="0.509105 0.509044 0.490967 0.490548" mass="0.00478125" diaginertia="4.07603e-07 3.57283e-07 1.57379e-07" />
                          <joint name="hand_left_middle_prox_joint" range="0 1.5708"/>
                          <geom class="visual" mesh="phalanx_link" />
                          <body name="hand_left_middle_mid_link" pos="-0.0258748 0 0">
                            <inertial pos="-0.0111483 9.28713e-05 -6.08808e-05" quat="0.509105 0.509044 0.490967 0.490548" mass="0.00478125" diaginertia="4.07603e-07 3.57283e-07 1.57379e-07" />
                            <joint name="hand_left_middle_mid_joint" range="0 1.5708"/>
                            <geom class="visual" mesh="phalanx_link" />
                            <body name="hand_left_middle_dist_link" pos="-0.0258748 0 0">
                              <inertial pos="-0.01044 -0.00064 -6e-05" quat="0.48992 0.51041 0.454557 0.541145" mass="0.00476" diaginertia="4.20832e-07 3.33472e-07 2.4112e-07" />
                              <joint name="hand_left_middle_dist_joint" range="0 1.5708"/>
                              <geom class="visual" mesh="tip_link" />
                            </body>
                          </body>
                        </body>
                        <body name="hand_left_ring_prox_link" pos="-0.081871 -0.001367 0.013029" quat="0.994169 0.0387077 0.0471293 0.0889293">
                          <inertial pos="-0.0111483 9.28713e-05 -6.08808e-05" quat="0.509105 0.509044 0.490967 0.490548" mass="0.00478125" diaginertia="4.07603e-07 3.57283e-07 1.57379e-07" />
                          <joint name="hand_left_ring_prox_joint" range="0 1.5708"/>
                          <geom class="visual" mesh="phalanx_link" />
                          <body name="hand_left_ring_mid_link" pos="-0.0258748 0 0">
                            <inertial pos="-0.0111483 9.28713e-05 -6.08808e-05" quat="0.509105 0.509044 0.490967 0.490548" mass="0.00478125" diaginertia="4.07603e-07 3.57283e-07 1.57379e-07" />
                            <joint name="hand_left_ring_mid_joint" range="0 1.5708"/>
                            <geom class="visual" mesh="phalanx_link" />
                            <body name="hand_left_ring_dist_link" pos="-0.0258748 0 0">
                              <inertial pos="-0.01044 -0.00064 -6e-05" quat="0.48992 0.51041 0.454557 0.541145" mass="0.00476" diaginertia="4.20832e-07 3.33472e-07 2.4112e-07" />
                              <joint name="hand_left_ring_dist_joint" range="0 1.5708"/>
                              <geom class="visual" mesh="tip_link" />
                            </body>
                          </body>
                        </body>
                        <body name="hand_left_small_prox_link" pos="-0.073142 -0.0034204 0.037631" quat="0.987966 0.0789269 0.0940585 0.09406">
                          <inertial pos="-0.0111483 9.28713e-05 -6.08808e-05" quat="0.509105 0.509044 0.490967 0.490548" mass="0.00478125" diaginertia="4.07603e-07 3.57283e-07 1.57379e-07" />
                          <joint name="hand_left_small_prox_joint" range="0 1.5708"/>
                          <geom class="visual" mesh="phalanx_link" />
                          <body name="hand_left_small_mid_link" pos="-0.0258748 0 0">
                            <inertial pos="-0.0111483 9.28713e-05 -6.08808e-05" quat="0.509105 0.509044 0.490967 0.490548" mass="0.00478125" diaginertia="4.07603e-07 3.57283e-07 1.57379e-07" />
                            <joint name="hand_left_small_mid_joint" range="0 1.5708"/>
                            <geom class="visual" mesh="phalanx_link" />
                            <body name="hand_left_small_dist_link" pos="-0.0258748 0 0">
                              <inertial pos="-0.01044 -0.00064 -6e-05" quat="0.48992 0.51041 0.454557 0.541145" mass="0.00476" diaginertia="4.20832e-07 3.33472e-07 2.4112e-07" />
                              <joint name="hand_left_small_dist_joint" range="0 1.5708"/>
                              <geom class="visual" mesh="tip_link" />
                            </body>
                          </body>
                        </body>
                        <body name="hand_left_thumb_base_link" pos="-0.036652 -0.00068435 -0.017088" quat="0.0907939 0.909338 -0.120867 0.387623">
                          <inertial pos="0.000390468 8.46232e-07 0.0168802" quat="0.998062 0.000353948 -0.0621625 -0.00279882" mass="0.00791208" diaginertia="7.19285e-07 7.0146e-07 4.03537e-07" />
                          <joint name="hand_left_thumb_base_joint" axis="0 0 -1" range="0 1.5708"/>
                          <geom class="visual" mesh="thumb_left_link" />
                          <body name="hand_left_thumb_methacarpal_link" pos="-0.011164 0 0.025271" quat="0.683011 0.683014 0.183013 -0.183013">
                            <inertial pos="-0.00901329 0.000112869 6.41889e-05" quat="0.512912 0.512904 0.486993 0.486507" mass="0.00393723" diaginertia="2.76407e-07 2.34526e-07 1.29465e-07" />
                            <joint name="hand_left_thumb_methacarpal_joint" range="0 1.5708"/>
                            <geom class="visual" mesh="thumb_phalanx_link" />
                            <body name="hand_left_thumb_proximal_link" pos="-0.021586 0 0">
                              <inertial pos="-0.00901329 0.000112869 6.41889e-05" quat="0.512912 0.512904 0.486993 0.486507" mass="0.00393723" diaginertia="2.76407e-07 2.34526e-07 1.29465e-07" />
                              <joint name="hand_left_thumb_proximal_joint" range="0 1.5708"/>
                              <geom class="visual" mesh="thumb_phalanx_link" />
                              <body name="hand_left_thumb_distal_link" pos="-0.021586 0 0">
                                <inertial pos="-0.01044 -0.00064 -6e-05" quat="0.48992 0.51041 0.454557 0.541145" mass="0.00476" diaginertia="4.20832e-07 3.33472e-07 2.4112e-07" />
                                <joint name="hand_left_thumb_distal_joint" range="0 1.5708"/>
                                <geom class="visual" mesh="tip_link" />
                              </body>
                            </body>
                          </body>
                        </body>
                      </body>
                    </body>
                  </body>
                </body>
              </body>
            </body>
          </body>
          <body name="arm_right_1_link" pos="0 -0.105954 0.390496" quat="-0.766035 0.642799 3.37752e-06 3.66665e-06">
            <inertial pos="0.0070639 0.0030301 -0.05724" quat="0.991252 0.0809813 -0.0910271 0.0507521" mass="1.1788" diaginertia="0.00192068 0.00177268 0.000875278" />
            <joint name="arm_right_1_joint" axis="0 0 -1" range="-2.61799 2.61799"/>
            <geom class="visual" mesh="arm1_link" />
            <!-- <geom size="0.0486559 0.0706888" pos="-0.0112961 -0.00871686 -0.0875926" quat="0.993843 -0.0674454 0.087908 1.78949e-08" class="collision"/> -->
            <body name="arm_right_2_link" pos="0.03711 0.02 -0.17011" quat="0.707105 0 0.707108 0">
              <inertial pos="0.029543 -0.0049762 -0.03224" quat="0.0848392 0.690549 -0.0139433 0.718157" mass="1.2955" diaginertia="0.00278545 0.00260446 0.00100708" />
              <joint name="arm_right_2_joint" range="-1.13446 2.44346"/>
              <geom class="visual" mesh="arm2_link" />
              <geom name="arm_right_2_collision" size="0.0645032 0.0664882" pos="-0.0638385 0.00999977 -0.0388" quat="0.659371 0.116779 0.742693 -1.43134e-06" class="collision"/>
              <body name="arm_right_3_link" pos="0.15989 -0.02 -0.03711" quat="0.707105 0 -0.707108 0">
                <inertial pos="-0.00706385 -0.00303013 -0.0572396" quat="0.991251 -0.0809737 0.0910312 0.0507756" mass="1.17879" diaginertia="0.00192065 0.00177272 0.000875276" />
                <joint name="arm_right_3_joint" axis="0 0 -1" range="-2.61799 2.61799"/>
                <geom class="visual" mesh="arm3_link" />
                <!-- <geom size="0.0661152 0.0583363" pos="0.00922975 0.00265488 -0.0826432" quat="0.180736 -0.514963 0.837942 5.70431e-07" class="collision"/> -->
                <body name="arm_right_4_link" pos="-0.03711 -0.02 -0.17011" quat="0.707105 0 -0.707108 0">
                  <inertial pos="-0.0666639 0.0102985 -0.0351108" quat="0.0552758 0.727273 -0.0700841 0.68052" mass="1.80676" diaginertia="0.00263554 0.00245424 0.00145523" />
                  <joint name="arm_right_4_joint" range="-1.13446 2.44346"/>
                  <geom class="visual" mesh="arm4_link" />
                  <geom name="arm_right_4_collision" size="0.0559132 0.220143" pos="0.210649 -0.0172373 -0.0265895" quat="0.717524 0.0513886 0.694636 -1.38234e-06" class="collision"/>
                  <body name="arm_right_5_link" pos="-0.17011 0.02 -0.03711" quat="0.707105 0 -0.707108 0">
                    <inertial pos="0.00582226 -0.000330137 0.0702339" quat="0.965441 -0.00213396 -0.0211456 0.259754" mass="0.73786" diaginertia="0.00302019 0.00300619 0.000658945" />
                    <joint name="arm_right_5_joint" axis="0 0 -1" range="-1.57 1.57"/>
                    <geom class="visual" mesh="arm5_tip_link" />
                    <geom pos="0 0 0.0303" quat="-0.707107 0 0 0.707106" class="visual" mesh="seedRobotics_adaptor" />
                    <geom pos="0 0 0.0498" quat="-1 0 0 0.000397654" class="visual" mesh="forearm_link" />
                    <!-- <body name="hand_right_palm_base_link" pos="0 0 0.2158" quat="0.000280246 -0.707105 0.000280245 0.707108">
                      <inertial pos="0.00858508 -2.4614e-09 0.000249999" quat="0.5 0.5 -0.5 0.5" mass="0.0509809" diaginertia="1.88432e-05 1.37535e-05 9.79678e-06" />
                      <joint name="hand_right_palm_roll_joint" axis="0 0 -1" range="-0.785398 0.785398"/>
                      <geom class="visual" mesh="wrist_link" />
                      <body name="hand_right_palm_link" quat="0.707105 -0.707108 0 0">
                        <site name="ee_right" pos="0.0 0.0 0.0"/>
                        <inertial pos="-0.052625 0.000781495 -0.00275893" quat="0.740136 -0.0434134 -7.69336e-05 0.671055" mass="0.0389736" diaginertia="2.76787e-05 1.98299e-05 1.10229e-05" />
                        <joint name="hand_right_palm_pitch_joint" range="-0.785398 0.785398"/>
                        <geom class="visual" mesh="palm_right_link" />
                        <body name="hand_right_index_prox_link" pos="-0.081291 -0.0045543 0.036786" quat="0.991128 0.0829563 0.0508768 0.0905266">
                          <inertial pos="-0.0111483 9.28713e-05 -6.08808e-05" quat="0.509105 0.509044 0.490967 0.490548" mass="0.00478125" diaginertia="4.07603e-07 3.57283e-07 1.57379e-07" />
                          <joint name="hand_right_index_prox_joint" range="0 1.5708"/>
                          <geom class="visual" mesh="phalanx_link" />
                          <body name="hand_right_index_mid_link" pos="-0.0258748 0 0">
                            <inertial pos="-0.0111483 9.28713e-05 -6.08808e-05" quat="0.509105 0.509044 0.490967 0.490548" mass="0.00478125" diaginertia="4.07603e-07 3.57283e-07 1.57379e-07" />
                            <joint name="hand_right_index_mid_joint" range="0 1.5708"/>
                            <geom class="visual" mesh="phalanx_link" />
                            <body name="hand_right_index_dist_link" pos="-0.0258748 0 0">
                              <inertial pos="-0.01044 -0.00064 -6e-05" quat="0.48992 0.51041 0.454557 0.541145" mass="0.00476" diaginertia="4.20832e-07 3.33472e-07 2.4112e-07" />
                              <joint name="hand_right_index_dist_joint" range="0 1.5708"/>
                              <geom class="visual" mesh="tip_link" />
                            </body>
                          </body>
                        </body>
                        <body name="hand_right_middle_prox_link" pos="-0.082896 -0.0014507 0.011829" quat="0.995247 0.0434532 0.0038016 0.0870713">
                          <inertial pos="-0.0111483 9.28713e-05 -6.08808e-05" quat="0.509105 0.509044 0.490967 0.490548" mass="0.00478125" diaginertia="4.07603e-07 3.57283e-07 1.57379e-07" />
                          <joint name="hand_right_middle_prox_joint" range="0 1.5708"/>
                          <geom class="visual" mesh="phalanx_link" />
                          <body name="hand_right_middle_mid_link" pos="-0.0258748 0 0">
                            <inertial pos="-0.0111483 9.28713e-05 -6.08808e-05" quat="0.509105 0.509044 0.490967 0.490548" mass="0.00478125" diaginertia="4.07603e-07 3.57283e-07 1.57379e-07" />
                            <joint name="hand_right_middle_mid_joint" range="0 1.5708"/>
                            <geom class="visual" mesh="phalanx_link" />
                            <body name="hand_right_middle_dist_link" pos="-0.0258748 0 0">
                              <inertial pos="-0.01044 -0.00064 -6e-05" quat="0.48992 0.51041 0.454557 0.541145" mass="0.00476" diaginertia="4.20832e-07 3.33472e-07 2.4112e-07" />
                              <joint name="hand_right_middle_dist_joint" range="0 1.5708"/>
                              <geom class="visual" mesh="tip_link" />
                            </body>
                          </body>
                        </body>
                        <body name="hand_right_ring_prox_link" pos="-0.081871 -0.001367 -0.013029" quat="0.994169 -0.0387077 -0.0471293 0.0889293">
                          <inertial pos="-0.0111483 9.28713e-05 -6.08808e-05" quat="0.509105 0.509044 0.490967 0.490548" mass="0.00478125" diaginertia="4.07603e-07 3.57283e-07 1.57379e-07" />
                          <joint name="hand_right_ring_prox_joint" range="0 1.5708"/>
                          <geom class="visual" mesh="phalanx_link" />
                          <body name="hand_right_ring_mid_link" pos="-0.0258748 0 0">
                            <inertial pos="-0.0111483 9.28713e-05 -6.08808e-05" quat="0.509105 0.509044 0.490967 0.490548" mass="0.00478125" diaginertia="4.07603e-07 3.57283e-07 1.57379e-07" />
                            <joint name="hand_right_ring_mid_joint" range="0 1.5708"/>
                            <geom class="visual" mesh="phalanx_link" />
                            <body name="hand_right_ring_dist_link" pos="-0.0258748 0 0">
                              <inertial pos="-0.01044 -0.00064 -6e-05" quat="0.48992 0.51041 0.454557 0.541145" mass="0.00476" diaginertia="4.20832e-07 3.33472e-07 2.4112e-07" />
                              <joint name="hand_right_ring_dist_joint" range="0 1.5708"/>
                              <geom class="visual" mesh="tip_link" />
                            </body>
                          </body>
                        </body>
                        <body name="hand_right_small_prox_link" pos="-0.073142 -0.0034204 -0.037631" quat="0.987966 -0.0789269 -0.0940585 0.09406">
                          <inertial pos="-0.0111483 9.28713e-05 -6.08808e-05" quat="0.509105 0.509044 0.490967 0.490548" mass="0.00478125" diaginertia="4.07603e-07 3.57283e-07 1.57379e-07" />
                          <joint name="hand_right_small_prox_joint" range="0 1.5708"/>
                          <geom class="visual" mesh="phalanx_link" />
                          <body name="hand_right_small_mid_link" pos="-0.0258748 0 0">
                            <inertial pos="-0.0111483 9.28713e-05 -6.08808e-05" quat="0.509105 0.509044 0.490967 0.490548" mass="0.00478125" diaginertia="4.07603e-07 3.57283e-07 1.57379e-07" />
                            <joint name="hand_right_small_mid_joint" range="0 1.5708"/>
                            <geom class="visual" mesh="phalanx_link" />
                            <body name="hand_right_small_dist_link" pos="-0.0258748 0 0">
                              <inertial pos="-0.01044 -0.00064 -6e-05" quat="0.48992 0.51041 0.454557 0.541145" mass="0.00476" diaginertia="4.20832e-07 3.33472e-07 2.4112e-07" />
                              <joint name="hand_right_small_dist_joint" range="0 1.5708"/>
                              <geom class="visual" mesh="tip_link" />
                            </body>
                          </body>
                        </body>
                        <body name="hand_right_thumb_base_link" pos="-0.036652 -0.00068435 0.017088" quat="0.00427349 0.91385 -0.0798969 -0.398092">
                          <inertial pos="0.000390468 8.46232e-07 0.0168802" quat="0.998062 0.000353948 -0.0621625 -0.00279882" mass="0.00791208" diaginertia="7.19285e-07 7.0146e-07 4.03537e-07" />
                          <joint name="hand_right_thumb_base_joint" axis="0 0 -1" range="0 1.5708"/>
                          <geom class="visual" mesh="thumb_right_link" />
                          <body name="hand_right_thumb_methacarpal_link" pos="-0.011164 0 -0.025271" quat="0.683011 -0.683014 -0.183013 -0.183013">
                            <inertial pos="-0.00901329 0.000112869 6.41889e-05" quat="0.512912 0.512904 0.486993 0.486507" mass="0.00393723" diaginertia="2.76407e-07 2.34526e-07 1.29465e-07" />
                            <joint name="hand_right_thumb_methacarpal_joint" range="0 1.5708"/>
                            <geom class="visual" mesh="thumb_phalanx_link" />
                            <body name="hand_right_thumb_proximal_link" pos="-0.021586 0 0">
                              <inertial pos="-0.00901329 0.000112869 6.41889e-05" quat="0.512912 0.512904 0.486993 0.486507" mass="0.00393723" diaginertia="2.76407e-07 2.34526e-07 1.29465e-07" />
                              <joint name="hand_right_thumb_proximal_joint" range="0 1.5708"/>
                              <geom class="visual" mesh="thumb_phalanx_link" />
                              <body name="hand_right_thumb_distal_link" pos="-0.021586 0 0">
                                <inertial pos="-0.01044 -0.00064 -6e-05" quat="0.48992 0.51041 0.454557 0.541145" mass="0.00476" diaginertia="4.20832e-07 3.33472e-07 2.4112e-07" />
                                <joint name="hand_right_thumb_distal_joint" range="0 1.5708"/>
                                <geom class="visual" mesh="tip_link" />
                              </body>
                            </body>
                          </body>
                        </body>
                      </body>
                    </body> -->
                  </body>
                </body>
              </body>
            </body>
          </body>
        </body>
      </body>
      <body name="leg_left_1_link" pos="-0.0150026 0.08 -0.0585">
        <inertial pos="0.0063167 0.0045949 -0.0083828" quat="0.99829 -0.0115969 -0.0468646 0.0329665" mass="2.7478" diaginertia="0.00193869 0.00182214 0.00142127" />
        <joint name="leg_left_1_joint" range="-0.261799 0.698132"/>
        <geom class="visual" mesh="leg_left_1_link" />
        <!-- <geom name="leg_left_1_collision" size="0.0795723 0.0413497" pos="-0.0236664 0.00650664 -0.00579961" quat="0.539802 0.154604 0.827473 1.45962e-06" class="collision"/> -->
        <body name="leg_left_2_link" pos="0.015024 0 -0.1175">
          <inertial pos="-0.0029278 -9.6207e-05 1.0866e-09" quat="0.500354 0.500354 0.499645 0.499645" mass="0.0905312" diaginertia="3.88542e-05 3.62287e-05 6.1016e-06" />
          <joint name="leg_left_2_joint" axis="0 1 0" range="-0.741765 0.663225"/>
          <geom class="visual" mesh="leg_left_2_link" />
          <body name="leg_left_3_link">
            <inertial pos="-0.033949 0.049989 -0.030543" quat="0.0645597 0.615939 -0.131914 0.773983" mass="3.658" diaginertia="0.00327114 0.00320831 0.00250706" />
            <joint name="leg_left_3_joint" axis="1 0 0" range="-0.471239 0.471239"/>
            <geom class="visual" mesh="leg_left_3_link" />
            <body name="leg_left_length_link" pos="0 0.0669 -0.09" quat="0 0 1 0">
              <inertial mass="0.1" pos="0 0 0" diaginertia="8.58333e-05 8.58333e-05 5e-06"/>
              <joint name="leg_left_length_joint" type="slide" range="0.131973 0.714166"/>
              <geom size="5e-05 0.291097" pos="0 0 -0.291097" type="cylinder" contype="0" conaffinity="0" group="1" density="0" />
              <body name="leg_left_4_link" quat="-0.173648 0 0.984808 0">
                <inertial pos="-0.00759995 -6.94998e-09 5.88281e-08" quat="3.61787e-06 0.707107 3.61787e-06 0.707106" mass="0.0905838" diaginertia="2.98863e-05 2.92763e-05 4.05264e-06" />
                <joint name="leg_left_4_joint" axis="0 1 0" range="-0.741765 0.663225"/>
                <geom quat="0.984808 0 -0.173648 0" class="visual" mesh="leg_6_link" />
                <body name="leg_left_5_link">
                  <inertial pos="0.00560127 -5.98529e-06 -0.0297244" quat="-8.95501e-06 0.58162 -1.58775e-05 0.813461" mass="0.61563" diaginertia="0.0019868 0.00170803 0.000338695" />
                  <joint name="leg_left_5_joint" axis="-1 0 0" range="-0.471239 0.471239"/>
                  <geom class="visual" mesh="leg_7_link" />
                  <geom name="left_foot_collision" size="0.045 0.01 0.1205" pos="0.01305 0 -0.03" quat="0.579228 0.40558 0.40558 0.579228" type="box" group="3" material="bright_orange"/>
                  <site name="left_foot" pos="0.0575 0 -0.01" size="0.015"/>
                </body>
              </body>
            </body>
            <body name="leg_left_femur_link" pos="0 0.0669 -0.09" quat="0.819152 0 -0.573576 0">
              <inertial pos="0.0527475 0.000135688 -0.146959" quat="0.720223 -0.0942418 -0.0980078 0.680288" mass="3.94567" diaginertia="0.0121138 0.0118241 0.00184947" />
              <joint name="leg_left_femur_joint" axis="0 1 0" range="0.174533 1.22173"/>
              <geom class="visual" mesh="leg_femur_link" />
              <geom name="leg_left_femur_collision" size="0.0910718 0.15" pos="0.043456 0.000622273 -0.115825" quat="0.194464 0.00344037 0.980904 2.41185e-06" class="collision"/>
              <body name="leg_left_knee_link" pos="0.129945 0 -0.357092" quat="0.34202 0 0.939693 0">
                <inertial pos="-0.0569665 -5.4131e-05 -0.148821" quat="0.698616 0.0970713 0.0960701 0.702341" mass="1.02238" diaginertia="0.00215347 0.00207236 0.000258578" />
                <joint name="leg_left_knee_joint" axis="0 -1 0" range="0.349066 2.44346"/>
                <geom class="visual" mesh="leg_tibia_link" />
                <geom name="leg_left_knee_collision" size="0.04 0.12" pos="-0.0455604 -7.35027e-05 -0.174883" quat="0.963852 -0.000204 0.266438 1.8e-05" class="collision"/>
              </body>
            </body>
          </body>
        </body>
      </body>
      <body name="leg_right_1_link" pos="-0.0150026 -0.08 -0.0585">
        <inertial pos="0.0063167 -0.0045949 -0.0083828" quat="0.998081 0.0061833 0.0472134 -0.0395937" mass="2.7478" diaginertia="0.00193889 0.00182188 0.00142133" />
        <joint name="leg_right_1_joint" range="-0.698132 0.261799"/>
        <geom class="visual" mesh="leg_right_1_link" />
        <!-- <geom name="leg_right_1_collision" size="0.0795723 0.0413497" pos="-0.0236664 -0.00650664 -0.00579961" quat="0.539802 -0.154604 0.827473 -1.45962e-06" class="collision"/> -->
        <body name="leg_right_2_link" pos="0.015024 0 -0.1175">
          <inertial pos="-0.0029278 -9.6207e-05 1.0866e-09" quat="0.500354 0.500354 0.499645 0.499645" mass="0.0905312" diaginertia="3.88542e-05 3.62287e-05 6.1016e-06" />
          <joint name="leg_right_2_joint" axis="0 1 0" range="-0.741765 0.663225"/>
          <geom class="visual" mesh="leg_right_2_link" />
          <body name="leg_right_3_link">
            <inertial pos="-0.033949 -0.049989 -0.030543" quat="-0.276874 0.75747 -0.131896 0.576353" mass="3.658" diaginertia="0.00331808 0.0031534 0.00251503" />
            <joint name="leg_right_3_joint" axis="1 0 0" range="-0.471239 0.471239"/>
            <geom class="visual" mesh="leg_right_3_link" />
            <body name="leg_right_length_link" pos="0 -0.0669 -0.09" quat="0 0 1 0">
              <inertial mass="0.1" pos="0 0 0" diaginertia="8.58333e-05 8.58333e-05 5e-06"/>
              <joint name="leg_right_length_joint" type="slide" range="0.131973 0.714166"/>
              <geom size="5e-05 0.291097" pos="0 0 -0.291097" type="cylinder" contype="0" conaffinity="0" group="1" density="0" />
              <body name="leg_right_4_link" quat="-0.173648 0 0.984808 0">
                <inertial pos="-0.00759995 -6.94998e-09 5.88281e-08" quat="3.61787e-06 0.707107 3.61787e-06 0.707106" mass="0.0905838" diaginertia="2.98863e-05 2.92763e-05 4.05264e-06" />
                <joint name="leg_right_4_joint" axis="0 1 0" range="-0.741765 0.663225"/>
                <geom quat="0.984808 0 -0.173648 0" class="visual" mesh="leg_6_link" />
                <body name="leg_right_5_link">
                  <inertial pos="0.00560127 -5.98529e-06 -0.0297244" quat="-8.95501e-06 0.58162 -1.58775e-05 0.813461" mass="0.61563" diaginertia="0.0019868 0.00170803 0.000338695" />
                  <joint name="leg_right_5_joint" axis="-1 0 0" range="-0.471239 0.471239"/>
                  <geom class="visual" mesh="leg_7_link" />
                  <site name="right_foot" pos="0.0575 0 -0.01" size="0.015"/>
                  <geom name="right_foot_collision" size="0.045 0.01 0.1205" pos="0.01305 0 -0.03" quat="0.579228 0.40558 0.40558 0.579228" type="box" group="3" material="bright_orange"/>
                </body>
              </body>
            </body>
            <body name="leg_right_femur_link" pos="0 -0.0669 -0.09" quat="0.819152 0 -0.573576 0">
              <inertial pos="0.0527475 0.000135688 -0.146959" quat="0.720223 -0.0942418 -0.0980078 0.680288" mass="3.94567" diaginertia="0.0121138 0.0118241 0.00184947" />
              <joint name="leg_right_femur_joint" axis="0 1 0" range="0.174533 1.22173"/>
              <geom class="visual" mesh="leg_femur_link" />
              <geom name="leg_right_femure_collision" size="0.0910718 0.15" pos="0.043456 0.000622273 -0.115825" quat="0.194464 0.00344037 0.980904 2.41185e-06" class="collision"/>
              <body name="leg_right_knee_link" pos="0.129945 0 -0.357092" quat="0.34202 0 0.939693 0">
                <inertial pos="-0.0569665 -5.4131e-05 -0.148821" quat="0.698616 0.0970713 0.0960701 0.702341" mass="1.02238" diaginertia="0.00215347 0.00207236 0.000258578" />
                <joint name="leg_right_knee_joint" axis="0 -1 0" range="0.349066 2.44346"/>
                <geom class="visual" mesh="leg_tibia_link" />
                <geom name="leg_right_knee_collision" size="0.04 0.12" pos="-0.0455604 -7.35027e-05 -0.174883" quat="0.963852 -0.000204 0.266438 1.8e-05" class="collision"/>
              </body>
            </body>
          </body>
        </body>
      </body>
    </body>
  </worldbody>

  <!--<actuator>
    <position ctrlrange=" 0.0 1.57 " joint="hand_left_index_prox_joint" kp="100" name="hand_left_index_position" />
    <position ctrlrange=" 0.0 1.57 " joint="hand_left_middle_prox_joint" kp="100" name="hand_left_middle_position" />
    <position ctrlrange=" 0.0 1.57 " joint="hand_left_ring_prox_joint" kp="100" name="hand_left_ring_small_position" />
    <position ctrlrange=" 0.0 1.57 " joint="hand_left_thumb_methacarpal_joint" kp="100" name="hand_left_thumb_position" />
    <position ctrlrange=" -0.785 0.785 " joint="hand_left_palm_roll_joint" kp="100" name="hand_left_palm_roll_position" />
    <position ctrlrange=" -0.785 0.785 " joint="hand_left_palm_pitch_joint" kp="100" name="hand_left_palm_pitch_position" />
    <position ctrlrange=" 0 1.571 " joint="hand_left_thumb_base_joint" kp="100" name="hand_left_thum_base_position" />
    <position ctrlrange=" 0.0 1.57 " joint="hand_right_index_prox_joint" kp="100" name="hand_right_index_position" />
    <position ctrlrange=" 0.0 1.57 " joint="hand_right_middle_prox_joint" kp="100" name="hand_right_middle_position" />
    <position ctrlrange=" 0.0 1.57 " joint="hand_right_ring_prox_joint" kp="100" name="hand_right_ring_small_position" />
    <position ctrlrange=" 0.0 1.57 " joint="hand_right_thumb_methacarpal_joint" kp="100" name="hand_right_thumb_position" />
    <position ctrlrange=" -0.785 0.785 " joint="hand_right_palm_roll_joint" kp="100" name="hand_right_palm_roll_position" />
    <position ctrlrange=" -0.785 0.785 " joint="hand_right_palm_pitch_joint" kp="100" name="hand_right_palm_pitch_position" />
    <position ctrlrange=" 0 1.571 " joint="hand_right_thumb_base_joint" kp="100" name="hand_right_thum_base_position" />
  </actuator>-->

  <equality>
    <connect name="leg_left_closed_kin_joint" body1="leg_left_4_link" body2="leg_left_knee_link" anchor="0 0 0" solref="0.002"/>
    <connect name="leg_right_closed_kin_joint" body1="leg_right_4_link" body2="leg_right_knee_link" anchor="0 0 0" solref="0.002"/>
    <joint joint1="hand_left_thumb_methacarpal_joint" joint2="hand_left_thumb_proximal_joint" name="hand_left_thumb_1_eq" polycoef="0 1 0 0 0" solimp="0.95 0.99 0.001" solref="0.005 1" />
    <joint joint1="hand_left_thumb_methacarpal_joint" joint2="hand_left_thumb_distal_joint" name="hand_left_thumb_2_eq" polycoef="0 1 0 0 0" solimp="0.95 0.99 0.001" solref="0.005 1" />
    <joint joint1="hand_left_index_prox_joint" joint2="hand_left_index_mid_joint" name="hand_left_index_1_eq" polycoef="0 1 0 0 0" solimp="0.95 0.99 0.001" solref="0.005 1" />
    <joint joint1="hand_left_index_prox_joint" joint2="hand_left_index_dist_joint" name="hand_left_index_2_eq" polycoef="0 1 0 0 0" solimp="0.95 0.99 0.001" solref="0.005 1" />
    <joint joint1="hand_left_middle_prox_joint" joint2="hand_left_middle_mid_joint" name="hand_left_middle_1_eq" polycoef="0 1 0 0 0" solimp="0.95 0.99 0.001" solref="0.005 1" />
    <joint joint1="hand_left_middle_prox_joint" joint2="hand_left_middle_dist_joint" name="hand_left_middle_2_eq" polycoef="0 1 0 0 0" solimp="0.95 0.99 0.001" solref="0.005 1" />
    <joint joint1="hand_left_ring_prox_joint" joint2="hand_left_ring_mid_joint" name="hand_left_ring_1_eq" polycoef="0 1 0 0 0" solimp="0.95 0.99 0.001" solref="0.005 1" />
    <joint joint1="hand_left_ring_prox_joint" joint2="hand_left_ring_dist_joint" name="hand_left_ring_2_eq" polycoef="0 1 0 0 0" solimp="0.95 0.99 0.001" solref="0.005 1" />
    <joint joint1="hand_left_ring_prox_joint" joint2="hand_left_small_prox_joint" name="hand_left_small_1_eq" polycoef="0 1 0 0 0" solimp="0.95 0.99 0.001" solref="0.005 1" />
    <joint joint1="hand_left_ring_prox_joint" joint2="hand_left_small_mid_joint" name="hand_left_small_2_eq" polycoef="0 1 0 0 0" solimp="0.95 0.99 0.001" solref="0.005 1" />
    <joint joint1="hand_left_ring_prox_joint" joint2="hand_left_small_dist_joint" name="hand_left_small_3_eq" polycoef="0 1 0 0 0" solimp="0.95 0.99 0.001" solref="0.005 1" />
    <joint joint1="hand_right_thumb_methacarpal_joint" joint2="hand_right_thumb_proximal_joint" name="hand_right_thumb_1_eq" polycoef="0 1 0 0 0" solimp="0.95 0.99 0.001" solref="0.005 1" />
    <joint joint1="hand_right_thumb_methacarpal_joint" joint2="hand_right_thumb_distal_joint" name="hand_right_thumb_2_eq" polycoef="0 1 0 0 0" solimp="0.95 0.99 0.001" solref="0.005 1" />
    <joint joint1="hand_right_index_prox_joint" joint2="hand_right_index_mid_joint" name="hand_right_index_1_eq" polycoef="0 1 0 0 0" solimp="0.95 0.99 0.001" solref="0.005 1" />
    <joint joint1="hand_right_index_prox_joint" joint2="hand_right_index_dist_joint" name="hand_right_index_2_eq" polycoef="0 1 0 0 0" solimp="0.95 0.99 0.001" solref="0.005 1" />
    <joint joint1="hand_right_middle_prox_joint" joint2="hand_right_middle_mid_joint" name="hand_right_middle_1_eq" polycoef="0 1 0 0 0" solimp="0.95 0.99 0.001" solref="0.005 1" />
    <joint joint1="hand_right_middle_prox_joint" joint2="hand_right_middle_dist_joint" name="hand_right_middle_2_eq" polycoef="0 1 0 0 0" solimp="0.95 0.99 0.001" solref="0.005 1" />
    <joint joint1="hand_right_ring_prox_joint" joint2="hand_right_ring_mid_joint" name="hand_right_ring_1_eq" polycoef="0 1 0 0 0" solimp="0.95 0.99 0.001" solref="0.005 1" />
    <joint joint1="hand_right_ring_prox_joint" joint2="hand_right_ring_dist_joint" name="hand_right_ring_2_eq" polycoef="0 1 0 0 0" solimp="0.95 0.99 0.001" solref="0.005 1" />
    <joint joint1="hand_right_ring_prox_joint" joint2="hand_right_small_prox_joint" name="hand_right_small_1_eq" polycoef="0 1 0 0 0" solimp="0.95 0.99 0.001" solref="0.005 1" />
    <joint joint1="hand_right_ring_prox_joint" joint2="hand_right_small_mid_joint" name="hand_right_small_2_eq" polycoef="0 1 0 0 0" solimp="0.95 0.99 0.001" solref="0.005 1" />
    <joint joint1="hand_right_ring_prox_joint" joint2="hand_right_small_dist_joint" name="hand_right_small_3_eq" polycoef="0 1 0 0 0" solimp="0.95 0.99 0.001" solref="0.005 1" />
  </equality>

  <!-- <keyframe>
    <key 
      ctrl="0 0 0.24 1.32 1.57 0.8 0.0 -0.24 
      1.32 -1.57 0.8 0.0 0 0.05 0 0.6 -0.07 
      0 0 0.05 0 0.6 -0.07 0 0 0 0 0 0 0 0 
      0 0 0 0 0 0 0" 
      name="home" 
      qpos="0 0 0.95 1 0 0 0 0 0 0.24 1.32 
      1.57 0.8 0.0 1.17971e-06 0.00257644 
      1.44184e-05 0.000670623 0.000512289 
      1.45929e-05 0.000673898 0.000514741 
      2.91036e-05 0.000688241 0.000529063 
      0.000621522 0.000684717 0.000526768 
      0.00012568 -6.97226e-05 -0.00216582 
      -0.000943487  -0.24 1.32 -1.57 0.8 
      0.0 1.17971e-06 0.00257644 1.44184e-05 
      0.000670623 0.000512289 1.45929e-05 
      0.000673898 0.000514741 2.91036e-05 
      0.000688241 0.000529063 0.000621522 
      0.000684717 0.000526768 0.00012568 
      -6.97226e-05 -0.00216582 -0.000943487 
      0 0.05 0 0.6 -0.07 0 0.9 1.8 0 0.05 
      0 0.6 -0.07 0 0.9 1.8"
    />
  </keyframe> -->
    
  <sensor>
    <gyro name="imu_ang_vel" site="imu"/>
    <velocimeter name="imu_lin_vel" site="imu"/>
    <accelerometer name="imu_lin_acc" site="imu"/>
    <subtreeangmom name="root_angmom" body="base_link"/>
  </sensor>
</mujoco>