<mujoco model="kangaroo">
  <compiler angle="radian" meshdir="assets" autolimits="true"/>

  <default>
    <default class="kangaroo">
      <!-- stiffer contact (solref="0.002 1") worsened sim2real, using defaults -->
      <!-- <geom solref="0.002 1" priority="1"/> -->
      <site group="5" rgba="1 0 0 1" size="0.01" />
      <default class="visual">
          <geom type="mesh" contype="0" conaffinity="0" group="2" density="0" material="dark_gray"/>
      </default>
      <default class="collision">
          <geom type="capsule" group="3" material="bright_orange" contype="1" conaffinity="1"/>
          <default class="foot_capsule">
            <geom type="capsule" size="0.01"/>
          </default>
      </default>
    </default>
  </default>

  <asset>
    <!-- materials -->
    <material name="dark_gray"      rgba="0.298039 0.298039 0.298039 1"/>
    <material name="bright_orange"  rgba="1 0.65 0 0.2"/>
    <!-- meshes -->
    <mesh name="leg_7_link"               content_type="model/stl" file="leg/leg_left_7_link.STL" />
    <mesh name="leg_7_link1"              content_type="model/stl" file="leg/leg_right_7_link.STL"/>


    <mesh file="full/base_link_with_pelvis/base_link_with_pelvis.obj"/>
    <mesh file="full/handle/handle.obj"/>
    <mesh file="full/pelvis_base_link/pelvis_base_link.obj"/>
    <mesh file="full/pelvis_1_link/pelvis_1_link.obj"/>
    <mesh file="full/pelvis_2_link/pelvis_2_link.obj"/>
    <mesh file="full/torso_link/torso_link.obj"/>
    <mesh file="full/leg_left_1_link/leg_left_1_link.obj"/>
    <mesh file="full/leg_left_2_link/leg_left_2_link.obj"/>
    <mesh file="full/leg_left_3_link/leg_left_3_link.obj"/>
    <mesh file="full/leg_4_collision_link/leg_4_collision_link.obj"/>
    <mesh file="full/leg_tibia_link/leg_tibia_link.obj"/>
    <mesh file="full/leg_6_link/leg_6_link.obj"/>
    <mesh file="full/leg_right_1_link/leg_right_1_link.obj"/>
    <mesh file="full/leg_right_2_link/leg_right_2_link.obj"/>
    <mesh file="full/leg_right_3_link/leg_right_3_link.obj"/>
    <mesh file="full/arm_base_link/arm_base_link.obj"/>
    <mesh file="full/arm1_link/arm1_link.obj"/>
    <mesh file="full/arm2_link/arm2_link.obj"/>
    <mesh file="full/arm3_link/arm3_link.obj"/>
    <mesh file="full/fake_forearm_left_link/fake_forearm_left_link.obj"/>
    <mesh file="full/fake_forearm_right_link/fake_forearm_right_link.obj"/>
  </asset>

  <worldbody>
    <body name="base_link" pos="0 0 0.9" childclass="kangaroo">
      <!-- <joint name="origin" type="free" /> -->
      <inertial pos="-0.098278 0.0050886 -0.0322547" quat="0.522568 0.510641 -0.490042 0.475423" mass="2.6738" diaginertia="0.0278602 0.0228122 0.00833063"/>
      <body name="back_handle">
        <inertial pos="-0.1742 2.256e-05 -0.0026718" quat="0.350797 0.350792 -0.613958 0.613957" mass="0.32489" diaginertia="0.00645011 0.00511549 0.0015135"/>
        <geom material="dark_gray" mesh="handle" class="visual"/>
      </body>
      <body name="pelvis_base_link" pos="-0.0918 0 -0.0455">
        <inertial pos="-0.020292 -0.000245 0.050005" quat="0.550147 0.448127 0.53674 0.456543" mass="1.82385" diaginertia="0.00796035 0.00789077 0.00167288"/>
        <body name="pelvis_1_link" pos="0 0 0.052" quat="0.707105 0 0.707108 0">
          <inertial pos="-0.02593 -1e-06 0.001466" quat="0.99984 0 -0.0179004 0" mass="1.24856" diaginertia="0.00539676 0.004808 0.00324424"/>
          <joint name="pelvis_1_joint" axis="0 0 -1" range="-0.349066 0.349066" actuatorfrcrange="-100 100"/>
          <body name="pelvis_2_link" pos="-0.0591 0 0" quat="0.707105 0 -0.707108 0">
            <inertial pos="0 0 -0.011136" quat="-0.0905443 0.701286 0.0905443 0.701286" mass="0.435922" diaginertia="0.001275 0.000674889 0.000630111"/>
            <joint name="pelvis_2_joint" axis="0 0 -1" range="-1.309 1.309" actuatorfrcrange="-100 100"/>
            <body name="torso_link" pos="0 0 0.0061">
              <inertial pos="-0.01 -0.00074 0.22222" quat="0.999849 0.0118442 0.0046843 -0.0118114" mass="13.3364" diaginertia="0.287967 0.266546 0.112048"/>
              <body name="imu_link" pos="0.071 -0.0014 0.02" quat="0 0.707107 -0.707107 0">
                <geom size="0.005 0.005 0.005" type="box" class="visual"/>
              </body>
              <body name="arm_left_base_link" pos="0 0.105954 0.384396" quat="0.642802 -0.766033 1.86923e-06 1.63502e-07">
                <inertial pos="0 0 0" mass="9.05e-07" diaginertia="0 0 0"/>
                <body name="arm_left_1_link" quat="1.34924e-11 -3.67321e-06 1 -3.67321e-06">
                  <inertial pos="0.0070639 0.0030301 -0.05724" quat="0.991252 0.0809813 -0.0910271 0.0507521" mass="1.1788" diaginertia="0.00192068 0.00177268 0.000875278"/>
                  <joint name="arm_left_1_joint" axis="0 0 -1" range="-2.61799 2.61799" actuatorfrcrange="-43 43"/>
                  <body name="arm_left_2_link" pos="0.03711 0.02 -0.17011" quat="0.707105 0 0.707108 0">
                    <inertial pos="0.029543 -0.0049762 -0.03224" quat="0.0848392 0.690549 -0.0139433 0.718157" mass="1.2955" diaginertia="0.00278545 0.00260446 0.00100708"/>
                    <joint name="arm_left_2_joint" axis="0 0 1" range="-1.13446 2.44346" actuatorfrcrange="-43 43"/>
                    <body name="arm_left_3_link" pos="0.15989 -0.02 -0.03711" quat="0.707105 0 -0.707108 0">
                      <inertial pos="-0.00706385 -0.00303013 -0.0572396" quat="0.991251 -0.0809737 0.0910312 0.0507756" mass="1.17879" diaginertia="0.00192065 0.00177272 0.000875276"/>
                      <joint name="arm_left_3_joint" axis="0 0 -1" range="-2.61799 2.61799" actuatorfrcrange="-43 43"/>
                      <body name="arm_left_4_link" pos="-0.03711 -0.02 -0.17011" quat="9.38184e-07 0.707105 9.38187e-07 -0.707108">
                        <inertial pos="0.0752641 -0.0079317 -0.023427" quat="0.573967 0.373833 0.602191 0.410095" mass="1.43535" diaginertia="0.0210305 0.0210101 0.00117153"/>
                        <joint name="arm_left_4_joint" axis="0 0 1" range="-1.1345 2.4435" actuatorfrcrange="-43 43"/>
                        <body name="arm_left_tool_link" pos="0.35 -0.02 -0.0255"/>
                        <geom material="dark_gray" mesh="fake_forearm_left_link" class="visual"/>
                        <site name="arm_left_tool_link" pos="0.35 -0.02 -0.0255"/>
                        <site name="arm_left_4_link"/>
                      </body>
                      <geom material="dark_gray" mesh="arm3_link" class="visual"/>
                      <site name="arm_left_3_link"/>
                    </body>
                    <geom material="dark_gray" mesh="arm2_link" class="visual"/>
                    <site name="arm_left_2_link"/>
                  </body>
                  <geom material="dark_gray" mesh="arm1_link" class="visual"/>
                  <site name="arm_left_1_link"/>
                </body>
                <geom material="dark_gray" mesh="arm_base_link" class="visual"/>
              </body>
              <body name="arm_right_base_link" pos="0 -0.105954 0.384396" quat="1.01637e-06 8.52866e-07 0.766033 -0.642802">
                <inertial pos="0 0 0" mass="9.05e-07" diaginertia="0 0 0"/>
                <body name="arm_right_1_link" quat="1.34924e-11 -3.67321e-06 1 -3.67321e-06">
                  <inertial pos="0.0070639 0.0030301 -0.05724" quat="0.991252 0.0809813 -0.0910271 0.0507521" mass="1.1788" diaginertia="0.00192068 0.00177268 0.000875278"/>
                  <joint name="arm_right_1_joint" axis="0 0 -1" range="-2.61799 2.61799" actuatorfrcrange="-43 43"/>
                  <body name="arm_right_2_link" pos="0.03711 0.02 -0.17011" quat="0.707105 0 0.707108 0">
                    <inertial pos="0.029543 -0.0049762 -0.03224" quat="0.0848392 0.690549 -0.0139433 0.718157" mass="1.2955" diaginertia="0.00278545 0.00260446 0.00100708"/>
                    <joint name="arm_right_2_joint" axis="0 0 1" range="-1.13446 2.44346" actuatorfrcrange="-43 43"/>
                    <body name="arm_right_3_link" pos="0.15989 -0.02 -0.03711" quat="0.707105 0 -0.707108 0">
                      <inertial pos="-0.00706385 -0.00303013 -0.0572396" quat="0.991251 -0.0809737 0.0910312 0.0507756" mass="1.17879" diaginertia="0.00192065 0.00177272 0.000875276"/>
                      <joint name="arm_right_3_joint" axis="0 0 -1" range="-2.61799 2.61799" actuatorfrcrange="-43 43"/>
                      <body name="arm_right_4_link" pos="-0.03711 -0.02 -0.17011" quat="9.38184e-07 0.707105 9.38187e-07 -0.707108">
                        <inertial pos="0.0752641 -0.0079317 -0.023427" quat="0.573967 0.373833 0.602191 0.410095" mass="1.43535" diaginertia="0.0210305 0.0210101 0.00117153"/>
                        <joint name="arm_right_4_joint" axis="0 0 1" range="-1.1345 2.4435" actuatorfrcrange="-43 43"/>
                        <body name="arm_right_tool_link" pos="0.35 -0.02 -0.0255"/>
                        <geom material="dark_gray" mesh="fake_forearm_right_link" class="visual"/>
                        <site name="arm_right_tool_link" pos="0.35 -0.02 -0.0255"/>
                        <site name="arm_right_4_link"/>
                      </body>
                      <geom material="dark_gray" mesh="arm3_link" class="visual"/>
                      <site name="arm_right_3_link"/>
                    </body>
                    <geom material="dark_gray" mesh="arm2_link" class="visual"/>
                    <site name="arm_right_2_link"/>
                  </body>
                  <geom material="dark_gray" mesh="arm1_link" class="visual"/>
                  <site name="arm_right_1_link"/>
                </body>
                <geom material="dark_gray" mesh="arm_base_link" class="visual"/>
              </body>
              <geom material="dark_gray" mesh="torso_link" class="visual"/>
            </body>
            <geom material="dark_gray" mesh="pelvis_2_link" class="visual"/>
            <site name="imu_link" pos="0.071 -0.0014 0.0261" quat="0 0.7071067811865476 -0.7071067811865475 0"/>
            <site name="pelvis_2_link"/>
            <site name="torso_link" pos="0 0 0.0061"/>
            <site name="arm_left_base_link" pos="0 0.105954 0.390496" quat="0.6428016275813444 -0.7660326804877542 1.8692341702116605e-06 1.6350233211185831e-07"/>
            <site name="arm_right_base_link" pos="0 -0.105954 0.390496" quat="1.016368251162654e-06 8.528659190506519e-07 0.7660326804895602 -0.6428016275805616"/>
          </body>
          <geom material="dark_gray" mesh="pelvis_1_link" class="visual"/>
          <site name="pelvis_1_link"/>
        </body>
        <geom material="dark_gray" mesh="pelvis_base_link" class="visual"/>
      </body>
      <body name="leg_left_1_link" pos="-0.0150026 0.08 -0.0585">
        <inertial pos="0.0063167 0.0045949 -0.0083828" quat="0.99829 -0.0115969 -0.0468646 0.0329665" mass="2.7478" diaginertia="0.00193869 0.00182214 0.00142127"/>
        <joint name="leg_left_1_joint" axis="0 0 1" range="-0.261799 0.698132" actuatorfrcrange="-80 80"/>
        <body name="leg_left_2_link" pos="0.015024 0 -0.1175">
          <inertial pos="-0.0029278 -9.6207e-05 1.0866e-09" quat="0.500354 0.500354 0.499645 0.499645" mass="0.0905312" diaginertia="3.88542e-05 3.62287e-05 6.1016e-06"/>
          <joint name="leg_left_2_joint" axis="0 1 0" range="-0.741765 0.663225" actuatorfrcrange="-230 230"/>
          <body name="leg_left_3_link">
            <inertial pos="-0.033949 0.049989 -0.030543" quat="0.0645597 0.615939 -0.131914 0.773983" mass="3.658" diaginertia="0.00327114 0.00320831 0.00250706"/>
            <joint name="leg_left_3_joint" axis="1 0 0" range="-0.471239 0.471239" actuatorfrcrange="-139 139"/>
            <body name="leg_left_length_link" pos="0 0.0669 -0.09" quat="0 0 1 0">
              <inertial pos="0 0 0" mass="0.1" diaginertia="8.58333e-05 8.58333e-05 5e-06"/>
              <joint name="leg_left_length_joint" axis="0 0 1" type="slide" range="0.131973 0.714166" actuatorfrcrange="-1100 1100"/>
              <body name="leg_left_4_link" quat="-0.173648 0 0.984808 0">
                <inertial pos="-0.00759995 -6.94998e-09 5.88281e-08" quat="3.61787e-06 0.707107 3.61787e-06 0.707106" mass="0.0905838" diaginertia="2.98863e-05 2.92763e-05 4.05264e-06"/>
                <joint name="leg_left_4_joint" axis="0 1 0" range="-0.741765 0.663225" actuatorfrcrange="-140 140"/>
                <body name="leg_left_5_link">
                  <inertial pos="0.00560127 -5.98529e-06 -0.0297244" quat="-8.95501e-06 0.58162 -1.58775e-05 0.813461" mass="0.61563" diaginertia="0.0019868 0.00170803 0.000338695"/>
                  <joint name="leg_left_5_joint" axis="-1 0 0" range="-0.471239 0.471239" actuatorfrcrange="-82 82"/>
                  <body name="leg_left_5_aligned_link" quat="0.984808 0 -0.173648 0">
                    <body name="left_sole_link" pos="0 0 -0.0425">
                      <body name="left_foot_upper_left" pos="0.115 0.045 0"/>
                      <body name="left_foot_upper_right" pos="0.115 -0.045 0"/>
                      <body name="left_foot_lower_left" pos="-0.095 0.045 0"/>
                      <body name="left_foot_lower_right" pos="-0.095 -0.045 0"/>
                    </body>
                  </body>
                  <geom material="dark_gray" mesh="leg_7_link" class="visual"/>
                  <site name="leg_left_5_link"/>
                  <site name="leg_left_5_aligned_link" quat="0.9848077530122079 0 -0.17364817766693036 0"/>
                  <site name="left_sole_link" pos="0.01453585609134092 0 -0.03993693638340111" quat="0.9848077530122079 0 -0.17364817766693036 0"/>
                  <site name="left_foot_upper_left" pos="0.12260050748172038 0.045 -0.0006046199009492118" quat="0.9848077530122079 0 -0.17364817766693036 0"/>
                  <site name="left_foot_upper_right" pos="0.12260050748172038 -0.045 -0.0006046199009492118" quat="0.9848077530122079 0 -0.17364817766693036 0"/>
                  <site name="left_foot_lower_left" pos="-0.07473494288332039 0.045 -0.07242884999933963" quat="0.9848077530122079 0 -0.17364817766693036 0"/>
                  <site name="left_foot_lower_right" pos="-0.07473494288332039 -0.045 -0.07242884999933963" quat="0.9848077530122079 0 -0.17364817766693036 0"/>
                </body>
                <geom material="dark_gray" mesh="leg_6_link" class="visual" quat="0.984808 0 -0.173648 0"/>
                <site name="leg_left_4_link"/>
              </body>
              <site name="leg_left_length_link"/>
            </body>
            <body name="leg_left_femur_link" pos="0 0.0669 -0.09" quat="0.819152 0 -0.573576 0">
              <inertial pos="0.0527475 0.000135688 -0.146959" quat="0.720223 -0.0942418 -0.0980078 0.680288" mass="3.94567" diaginertia="0.0121138 0.0118241 0.00184947"/>
              <joint name="leg_left_femur_joint" axis="0 1 0" range="0.174533 1.22173" actuatorfrcrange="-100 100"/>
              <body name="leg_left_knee_link" pos="0.129945 0 -0.357092" quat="0.34202 0 0.939693 0">
                <inertial pos="-0.0569665 -5.4131e-05 -0.148821" quat="0.698616 0.0970713 0.0960701 0.702341" mass="1.02238" diaginertia="0.00215347 0.00207236 0.000258578"/>
                <joint name="leg_left_knee_joint" axis="0 -1 0" range="0.349066 2.44346" actuatorfrcrange="-100 100"/>
                <body name="leg_left_knee_straight" quat="0.819152 0 -0.573576 0">
                  <body name="leg_left_knee_lower_bearing" pos="-0.38 0 0"/>
                </body>
                <geom material="dark_gray" mesh="leg_tibia_link" class="visual"/>
                <site name="leg_left_knee_link"/>
                <site name="leg_left_knee_straight" quat="0.8191520442889918 0 -0.573576436351046 0"/>
                <site name="leg_left_knee_lower_bearing" pos="-0.12996765446375416 0 -0.3570831958986452" quat="0.8191520442889918 0 -0.573576436351046 0"/>
              </body>
              <!-- <geom material="dark_gray" mesh="leg_tibia_link" class="visual" quat="0.866025 0 0.5 0"/> -->
              <geom material="dark_gray" mesh="leg_4_collision_link" class="visual" pos="0 0 0" quat="0.866025 0 0.5 0"/>
              <site name="leg_left_femur_link"/>
            </body>
            <geom material="dark_gray" mesh="leg_left_3_link" class="visual"/>
            <site name="leg_left_3_link"/>
          </body>
          <geom material="dark_gray" mesh="leg_left_2_link" class="visual"/>
          <site name="leg_left_2_link"/>
        </body>
        <geom material="dark_gray" mesh="leg_left_1_link" class="visual"/>
        <site name="leg_left_1_link"/>
      </body>
      <body name="leg_right_1_link" pos="-0.0150026 -0.08 -0.0585">
        <inertial pos="0.0063167 -0.0045949 -0.0083828" quat="0.998081 0.0061833 0.0472134 -0.0395937" mass="2.7478" diaginertia="0.00193889 0.00182188 0.00142133"/>
        <joint name="leg_right_1_joint" axis="0 0 1" range="-0.698132 0.261799" actuatorfrcrange="-80 80"/>
        <body name="leg_right_2_link" pos="0.015024 0 -0.1175">
          <inertial pos="-0.0029278 -9.6207e-05 1.0866e-09" quat="0.500354 0.500354 0.499645 0.499645" mass="0.0905312" diaginertia="3.88542e-05 3.62287e-05 6.1016e-06"/>
          <joint name="leg_right_2_joint" axis="0 1 0" range="-0.741765 0.663225" actuatorfrcrange="-230 230"/>
          <body name="leg_right_3_link">
            <inertial pos="-0.033949 -0.049989 -0.030543" quat="-0.276874 0.75747 -0.131896 0.576353" mass="3.658" diaginertia="0.00331808 0.0031534 0.00251503"/>
            <joint name="leg_right_3_joint" axis="1 0 0" range="-0.471239 0.471239" actuatorfrcrange="-139 139"/>
            <body name="leg_right_length_link" pos="0 -0.0669 -0.09" quat="0 0 1 0">
              <inertial pos="0 0 0" mass="0.1" diaginertia="8.58333e-05 8.58333e-05 5e-06"/>
              <joint name="leg_right_length_joint" axis="0 0 1" type="slide" range="0.131973 0.714166" actuatorfrcrange="-1100 1100"/>
              <body name="leg_right_4_link" quat="-0.173648 0 0.984808 0">
                <inertial pos="-0.00759995 -6.94998e-09 5.88281e-08" quat="3.61787e-06 0.707107 3.61787e-06 0.707106" mass="0.0905838" diaginertia="2.98863e-05 2.92763e-05 4.05264e-06"/>
                <joint name="leg_right_4_joint" axis="0 1 0" range="-0.741765 0.663225" actuatorfrcrange="-140 140"/>
                <body name="leg_right_5_link">
                  <inertial pos="0.00560127 -5.98529e-06 -0.0297244" quat="-8.95501e-06 0.58162 -1.58775e-05 0.813461" mass="0.61563" diaginertia="0.0019868 0.00170803 0.000338695"/>
                  <joint name="leg_right_5_joint" axis="-1 0 0" range="-0.471239 0.471239" actuatorfrcrange="-82 82"/>
                  <body name="leg_right_5_aligned_link" quat="0.984808 0 -0.173648 0">
                    <body name="right_sole_link" pos="0 0 -0.0425">
                      <body name="right_foot_upper_left" pos="0.115 0.045 0"/>
                      <body name="right_foot_upper_right" pos="0.115 -0.045 0"/>
                      <body name="right_foot_lower_left" pos="-0.095 0.045 0"/>
                      <body name="right_foot_lower_right" pos="-0.095 -0.045 0"/>
                    </body>
                  </body>
                  <geom material="dark_gray" mesh="leg_7_link" class="visual"/>
                  <site name="leg_right_5_link"/>
                  <site name="leg_right_5_aligned_link" quat="0.9848077530122079 0 -0.17364817766693036 0"/>
                  <site name="right_sole_link" pos="0.01453585609134092 0 -0.03993693638340111" quat="0.9848077530122079 0 -0.17364817766693036 0"/>
                  <site name="right_foot_upper_left" pos="0.12260050748172038 0.045 -0.0006046199009492118" quat="0.9848077530122079 0 -0.17364817766693036 0"/>
                  <site name="right_foot_upper_right" pos="0.12260050748172038 -0.045 -0.0006046199009492118" quat="0.9848077530122079 0 -0.17364817766693036 0"/>
                  <site name="right_foot_lower_left" pos="-0.07473494288332039 0.045 -0.07242884999933963" quat="0.9848077530122079 0 -0.17364817766693036 0"/>
                  <site name="right_foot_lower_right" pos="-0.07473494288332039 -0.045 -0.07242884999933963" quat="0.9848077530122079 0 -0.17364817766693036 0"/>
                </body>
                <geom material="dark_gray" mesh="leg_6_link" class="visual" quat="0.984808 0 -0.173648 0"/>
                <site name="leg_right_4_link"/>
              </body>
              <site name="leg_right_length_link"/>
            </body>
            <body name="leg_right_femur_link" pos="0 -0.0669 -0.09" quat="0.819152 0 -0.573576 0">
              <inertial pos="0.0527475 0.000135688 -0.146959" quat="0.720223 -0.0942418 -0.0980078 0.680288" mass="3.94567" diaginertia="0.0121138 0.0118241 0.00184947"/>
              <joint name="leg_right_femur_joint" axis="0 1 0" range="0.174533 1.22173" actuatorfrcrange="-100 100"/>
              <body name="leg_right_knee_link" pos="0.129945 0 -0.357092" quat="0.34202 0 0.939693 0">
                <inertial pos="-0.0569665 -5.4131e-05 -0.148821" quat="0.698616 0.0970713 0.0960701 0.702341" mass="1.02238" diaginertia="0.00215347 0.00207236 0.000258578"/>
                <joint name="leg_right_knee_joint" axis="0 -1 0" range="0.349066 2.44346" actuatorfrcrange="-100 100"/>
                <body name="leg_right_knee_straight" quat="0.819152 0 -0.573576 0">
                  <body name="leg_right_knee_lower_bearing" pos="-0.38 0 0"/>
                </body>
                <geom material="dark_gray" mesh="leg_tibia_link" class="visual"/>
                <site name="leg_right_knee_link"/>
                <site name="leg_right_knee_straight" quat="0.8191520442889918 0 -0.573576436351046 0"/>
                <site name="leg_right_knee_lower_bearing" pos="-0.12996765446375416 0 -0.3570831958986452" quat="0.8191520442889918 0 -0.573576436351046 0"/>
              </body>
              <geom material="dark_gray" mesh="leg_4_collision_link" class="visual" quat="0.866025 0 0.5 0"/>
              <site name="leg_right_femur_link"/>
            </body>
            <geom material="dark_gray" mesh="leg_right_3_link" class="visual"/>
            <site name="leg_right_3_link"/>
          </body>
          <geom material="dark_gray" mesh="leg_right_2_link" class="visual"/>
          <site name="leg_right_2_link"/>
        </body>
        <geom material="dark_gray" mesh="leg_right_1_link" class="visual"/>
        <site name="leg_right_1_link"/>
      </body>
      <geom material="dark_gray" mesh="base_link_with_pelvis" class="visual"/>
      <site name="base_link"/>
      <site name="back_handle"/>
      <site name="pelvis_base_link" pos="-0.0918000000000001 0 -0.0455"/>
    </body>
  </worldbody>

  <equality>
      <connect anchor="0.0 0.0 0.0" body1="leg_left_4_link" body2="leg_left_knee_link" name="leg_left_closed_kin_joint" solref="0.004 1" />
      <connect anchor="0.0 0.0 0.0" body1="leg_right_4_link" body2="leg_right_knee_link" name="leg_right_closed_kin_joint" solref="0.004 1" />
  </equality>

  <contact>
    <!-- Left leg closed chain -->
    <!-- <exclude body1="leg_left_1_link" body2="leg_left_femur_link"/>
    <exclude body1="leg_left_ankle_link" body2="leg_left_knee_link"/> -->
    
    <!-- Right leg closed chain -->
    <!-- <exclude body1="leg_right_1_link" body2="leg_right_femur_link"/>
    <exclude body1="leg_right_ankle_link" body2="leg_right_knee_link"/> -->
  </contact>
  
  <!-- <sensor>
    <gyro           name="imu_ang_vel" site="imu"/>
    <velocimeter    name="imu_lin_vel" site="imu"/>
    <accelerometer  name="imu_lin_acc" site="imu"/>
    <subtreeangmom  name="root_angmom" body="base_link"/>
    <framequat      name="imu_quat" objtype="site" objname="imu"/>
  </sensor> -->
</mujoco>