<mujoco model="kangaroo">
  <compiler angle="radian" meshdir="assets" autolimits="true"/>

  <default>
    <default class="kangaroo">
      <!-- stiffer contact (solref="0.002 1") worsened sim2real, using defaults -->
      <!-- <geom solref="0.002 1" priority="1"/> -->
      <site group="5" rgba="1 0 0 1" size="0.01" />
      <default class="visual">
          <geom type="mesh" contype="0" conaffinity="0" group="2" density="0" material="dark_gray"/>
      </default>
      <default class="collision">
          <geom type="capsule" group="3" material="bright_orange" contype="1" conaffinity="1"/>
          <default class="foot_capsule">
            <geom type="capsule" size="0.01"/>
          </default>
      </default>
    </default>
  </default>

  <asset>
    <!-- materials -->
    <material name="dark_gray"      rgba="0.298039 0.298039 0.298039 1"/>
    <material name="bright_orange"  rgba="1 0.65 0 0.2"/>
    <!-- meshes -->
    <mesh name="base_link_with_pelvis"    content_type="model/stl" file="base/base_link_with_pelvis.STL" />
    <mesh name="handle"                   content_type="model/stl" file="base/handle.STL" />
    <mesh name="pelvis_base_link"         content_type="model/stl" file="pelvis/pelvis_base_link.STL" />
    <mesh name="pelvis_1_link"            content_type="model/stl" file="pelvis/pelvis_1_link.STL" />
    <mesh name="pelvis_2_link"            content_type="model/stl" file="pelvis/pelvis_2_link.STL" />
    <mesh name="torso_link"               content_type="model/stl" file="torso/torso_link.STL" />
    <mesh name="leg_left_1_link"          content_type="model/stl" file="leg/leg_left_1_link.STL" />
    <mesh name="leg_left_2_link"          content_type="model/stl" file="leg/leg_left_2_link.STL" />
    <mesh name="leg_left_3_link"          content_type="model/stl" file="leg/leg_left_3_link.STL" />
    <mesh name="leg_6_link"               content_type="model/stl" file="leg/leg_left_6_link.STL" />
    <mesh name="leg_7_link"               content_type="model/stl" file="leg/leg_left_7_link.STL" />
    <mesh name="leg_right_1_link"         content_type="model/stl" file="leg/leg_right_1_link.STL" />
    <mesh name="leg_right_2_link"         content_type="model/stl" file="leg/leg_right_2_link.STL" />
    <mesh name="leg_right_3_link"         content_type="model/stl" file="leg/leg_right_3_link.STL" />
    <mesh name="leg_6_link1"              content_type="model/stl" file="leg/leg_right_6_link.STL"/>
    <mesh name="leg_7_link1"              content_type="model/stl" file="leg/leg_right_7_link.STL"/>
    <mesh name="leg_femur_link"           content_type="model/stl" file="leg/leg_femur_link.STL" />
    <mesh name="leg_tibia_link"           content_type="model/stl" file="leg/leg_tibia_link.STL" />
    <mesh name="arm_base_link"            content_type="model/stl" file="arm/arm_base_link.STL" />
    <mesh name="arm1_link"                content_type="model/stl" file="arm/arm1_link.STL" />
    <mesh name="arm2_link"                content_type="model/stl" file="arm/arm2_link.STL" />
    <mesh name="arm3_link"                content_type="model/stl" file="arm/arm3_link.STL" />
    <mesh name="fake_forearm_left_link"   content_type="model/stl" file="arm/fake_forearm_left_link.STL" />
    <mesh name="fake_forearm_right_link"  content_type="model/stl" file="arm/fake_forearm_right_link.STL" />
  </asset>

  <worldbody>
    <body name="base_link" pos="0 0 0.9" childclass="kangaroo">
      <inertial pos="-0.109992 -5e-05 -0.016543" quat="0.468526 0.46985 -0.528893 0.529147" mass="5.22758" diaginertia="0.0524932 0.0372729 0.0245289"/>
      <joint name="origin" type="free" />
      <geom class="visual" mesh="base_link_with_pelvis" />
      <geom class="visual" mesh="handle" />
      <geom pos="-0.0918 0 -0.0455" quat="1 0 0 0" class="visual" mesh="pelvis_base_link" />
      <body name="pelvis_1_link" pos="-0.0918 0 0.0065" quat="0.707105 0 0.707108 0">
        <inertial pos="-0.019996 -2e-06 0.003623" quat="0.999691 0 -0.0248385 0" mass="1.61061" diaginertia="0.00677426 0.006367 0.00383074"/>
        <joint name="pelvis_1_joint" axis="0 0 -1" range="-0.349066 0.349066" />
        <geom class="visual" mesh="pelvis_1_link" />
        <body name="pelvis_2_link" pos="-0.0591 0 0" quat="0.707105 0 -0.707108 0">
          <inertial pos="-0.009089 0.001579 0.230178" quat="0.999945 -0.00625629 -0.00226399 0.00816339" mass="15.1027" diaginertia="0.341764 0.310421 0.128899"/>
          <joint name="pelvis_2_joint" axis="0 0 -1" range="-1.309 1.309" />
          <geom class="visual" mesh="pelvis_2_link" />
          <geom pos="0 0 0.0061" quat="1 0 0 0" class="visual" mesh="torso_link" />
          <geom pos="0 0.105954 0.390496" quat="0.642802 -0.766033 1.86923e-06 1.63502e-07" class="visual" mesh="arm_base_link" />
          <geom pos="0 -0.105954 0.390496" quat="1.01637e-06 8.52866e-07 0.766033 -0.642802" class="visual" mesh="arm_base_link" />
          <geom name="pelvis_2_collision" size="0.163724 0.162985" pos="4.77798e-07 -1.67441e-06 0.234507" quat="1 -3.97075e-06 -1.19191e-05 0" class="collision"/>
          <site name="imu" pos="0.071 -0.0014 0.0261" quat="0 -0.707107 0.707107 0"/>
          <body name="arm_left_1_link" pos="0 0.105954 0.390496" quat="-4.68302e-06 -2.52466e-06 0.642799 -0.766035">
            <inertial pos="0.0070639 0.0030301 -0.05724" quat="0.991252 0.0809813 -0.0910271 0.0507521" mass="1.1788" diaginertia="0.00192068 0.00177268 0.000875278" />
            <joint name="arm_left_1_joint" axis="0 0 -1" range="-2.61799 2.61799" />
            <geom class="visual" mesh="arm1_link" />
            <body name="arm_left_2_link" pos="0.03711 0.02 -0.17011" quat="0.707105 0 0.707108 0">
              <inertial pos="0.029543 -0.0049762 -0.03224" quat="0.0848392 0.690549 -0.0139433 0.718157" mass="1.2955" diaginertia="0.00278545 0.00260446 0.00100708" />
              <joint name="arm_left_2_joint" range="-1.13446 2.44346" />
              <geom class="visual" mesh="arm2_link" />
              <body name="arm_left_3_link" pos="0.15989 -0.02 -0.03711" quat="0.707105 0 -0.707108 0">
                <inertial pos="-0.00706385 -0.00303013 -0.0572396" quat="0.991251 -0.0809737 0.0910312 0.0507756" mass="1.17879" diaginertia="0.00192065 0.00177272 0.000875276" />
                <joint name="arm_left_3_joint" axis="0 0 -1" range="-2.61799 2.61799" />
                <geom class="visual" mesh="arm3_link" />
                <body name="arm_left_4_link" pos="-0.03711 -0.02 -0.17011" quat="9.38184e-07 0.707105 9.38187e-07 -0.707108">
                  <inertial pos="0.0752641 -0.0079317 -0.023427" quat="0.573967 0.373833 0.602191 0.410095" mass="1.43535" diaginertia="0.0210305 0.0210101 0.00117153" />
                  <joint name="arm_left_4_joint" range="-1.1345 2.4435" />
                  <geom class="visual" mesh="fake_forearm_left_link" />
                  <geom name="arm_left_4_collision" size="0.054849 0.219217" pos="0.210246 -0.0167497 -0.0171982" quat="0.733112 0.0532001 0.678025 -2.2842e-07" class="collision"/>
                  <site name="ee_left" pos="0.45 -0.02 0.0"/>
                  <body name="arm_left_tip_link" pos="0.4 -0.02 0.0"/>
                </body>
              </body>
            </body>
          </body>
          <body name="arm_right_1_link" pos="0 -0.105954 0.390496" quat="-0.766035 0.642799 3.37752e-06 3.66665e-06">
            <inertial pos="0.0070639 0.0030301 -0.05724" quat="0.991252 0.0809813 -0.0910271 0.0507521" mass="1.1788" diaginertia="0.00192068 0.00177268 0.000875278" />
            <joint name="arm_right_1_joint" axis="0 0 -1" range="-2.61799 2.61799" />
            <geom class="visual" mesh="arm1_link" />
            <body name="arm_right_2_link" pos="0.03711 0.02 -0.17011" quat="0.707105 0 0.707108 0">
              <inertial pos="0.029543 -0.0049762 -0.03224" quat="0.0848392 0.690549 -0.0139433 0.718157" mass="1.2955" diaginertia="0.00278545 0.00260446 0.00100708" />
              <joint name="arm_right_2_joint" range="-1.13446 2.44346" />
              <geom class="visual" mesh="arm2_link" />
              <body name="arm_right_3_link" pos="0.15989 -0.02 -0.03711" quat="0.707105 0 -0.707108 0">
                <inertial pos="-0.00706385 -0.00303013 -0.0572396" quat="0.991251 -0.0809737 0.0910312 0.0507756" mass="1.17879" diaginertia="0.00192065 0.00177272 0.000875276" />
                <joint name="arm_right_3_joint" axis="0 0 -1" range="-2.61799 2.61799" />
                <geom class="visual" mesh="arm3_link" />
                <body name="arm_right_4_link" pos="-0.03711 -0.02 -0.17011" quat="9.38184e-07 0.707105 9.38187e-07 -0.707108">
                  <inertial pos="0.0752641 -0.0079317 -0.023427" quat="0.573967 0.373833 0.602191 0.410095" mass="1.43535" diaginertia="0.0210305 0.0210101 0.00117153" />
                  <joint name="arm_right_4_joint" range="-1.1345 2.4435" />
                  <geom class="visual" mesh="fake_forearm_right_link" />
                  <geom name="arm_right_4_collision" size="0.0559132 0.220143" pos="0.210649 -0.0172373 -0.0265895" quat="0.717524 0.0513886 0.694636 -1.38234e-06" class="collision"/>
                  <site name="ee_right" pos="0.45 -0.02 0.0"/>
                  <body name="arm_right_tip_link" pos="0.4 -0.02 0.0"/>
                </body>
              </body>
            </body>
          </body>
        </body>
      </body>
      <body name="leg_left_1_link" pos="-0.0150026 0.08 -0.0585">
        <inertial pos="0.049454 -3.7e-05 -0.064102" quat="0.990838 0.0490292 -0.125655 0.0069297" mass="2.77998" diaginertia="0.00819049 0.0061391 0.00582141"/>
        <joint name="leg_left_1_joint" range="-0.261799 0.698132" />
        <geom class="visual" mesh="leg_left_1_link" />
        <geom name="leg_left1_1_collision" size="0.04" fromto="0.07 -0.035 -0.03   0.07 -0.035 -0.015" class="collision"/>
        <body name="leg_left_2_link" pos="0.015024 0 -0.1175">
          <inertial pos="-0.005796 2.1e-05 -0.00014" quat="0.5 0.5 0.5 0.5" mass="0.104156" diaginertia="9.9e-05 9.6e-05 8e-06"/>
          <joint name="leg_left_2_joint" axis="0 1 0" range="-0.741765 0.663225" />
          <geom class="visual" mesh="leg_left_2_link" />
          <body name="leg_left_3_link">
            <inertial pos="-0.046481 0.055912 -0.037141" quat="0.671544 0.331073 -0.626854 0.215576" mass="3.70086" diaginertia="0.0218902 0.0169932 0.0110546"/>
            <joint name="leg_left_3_joint" axis="1 0 0" range="-0.471239 0.471239" />
            <geom class="visual" mesh="leg_left_3_link" />
            <body name="leg_left_length_link" pos="0 0.0669 -0.09" quat="0 0 1 0">
              <inertial mass="0.1" pos="0 0 0" diaginertia="8.58333e-05 8.58333e-05 5e-06" />
              <joint name="leg_left_length_joint" type="slide" range="0.131973 0.714166" />
              <geom size="5e-05 0.291097" pos="0 0 -0.291097" type="cylinder" class="visual" />
              <body name="leg_left_4_link" quat="-0.173648 0 0.984808 0">
                <inertial pos="-0.007727 0 0" quat="0 0.707107 0 0.707107" mass="0.086323" diaginertia="3.7e-05 3.5e-05 6e-06"/>
                <joint name="leg_left_4_joint" axis="0 1 0" range="-0.741765 0.663225" />
                <geom quat="0.984808 0 -0.173648 0" class="visual" mesh="leg_6_link" />
                <body name="leg_left_5_link">
                  <inertial pos="0.00560127 -5.98529e-06 -0.0297244" quat="-8.95501e-06 0.58162 -1.58775e-05 0.813461" mass="0.61563" diaginertia="0.0019868 0.00170803 0.000338695" />
                  <joint name="leg_left_5_joint" axis="-1 0 0" range="-0.471239 0.471239" />
                  <geom class="visual" mesh="leg_7_link" />
                  <site name="left_foot" pos="0.0575 0 -0.0243" size="0.015"/>
                  <body name="leg_left_foot_link" pos="0 0 -0.034" quat="0.9848078 0 -0.1736482 0">
                    <geom name="left_foot0_collision"  class="foot_capsule" fromto="-0.0830 -0.035 0 0.110 -0.0330 0"/>
                    <geom name="left_foot2_collision"  class="foot_capsule" fromto="-0.0975 -0.021 0 0.120 -0.0215 0"/>
                    <geom name="left_foot4_collision"  class="foot_capsule" fromto="-0.0985 -0.007 0 0.122 -0.0065 0"/>
                    <geom name="left_foot6_collision"  class="foot_capsule" fromto="-0.0985  0.007 0 0.122  0.0065 0"/>
                    <geom name="left_foot8_collision"  class="foot_capsule" fromto="-0.0975  0.021 0 0.120  0.0215 0"/>
                    <geom name="left_foot10_collision" class="foot_capsule" fromto="-0.0830  0.035 0 0.110  0.0330 0"/>
                    <body name="leg_left_ankle_link">
                      <geom name="leg_left_ankle_collision" class="collision" size="0.03" fromto="-0.04 0.0 0.03 0.02 0.0 0.03"/>
                      <geom name="leg_left_ankle_bar_collision" class="collision" size="0.03" fromto="-0.045 -0.035 0.05 -0.045 0.035 0.05"/>
                    </body>
                  </body>
                </body>
              </body>
            </body>
            <body name="leg_left_femur_link" pos="0 0.0669 -0.09" quat="0.819152 0 -0.573576 0">
              <inertial pos="0.055663 0.001808 -0.149159" quat="0.727287 0.0853086 0.0939168 0.674504" mass="4.92196" diaginertia="0.119103 0.117315 0.00884397"/>
              <joint name="leg_left_femur_joint" axis="0 1 0" range="0.174533 1.22173" />
              <geom class="visual" mesh="leg_femur_link" />
              <geom name="leg_left_femur_collision" size="0.0910718 0.2" pos="0.043456 0.000622273 -0.115825" quat="0.194464 0.00344037 0.980904 2.41185e-06" class="collision"/>
              <body name="leg_left_knee_link" pos="0.129945 0 -0.357092" quat="0.34202 0 0.939693 0">
                <inertial pos="-0.038219 -4.9e-05 -0.125673" quat="0.697566 -0.156834 -0.161666 0.680197" mass="0.915324" diaginertia="0.0146275 0.0139478 0.0013687"/>
                <joint name="leg_left_knee_joint" axis="0 -1 0" range="0.349066 2.44346" />
                <geom class="visual" mesh="leg_tibia_link" />
                <geom name="leg_left_knee_collision" size="0.04" fromto="-0.1483 0.0 -0.3 0.0571 0.0 -0.0033" class="collision"/>
                <geom name="leg_left_knee_bar_collision" class="collision" size="0.05" fromto="-0.05 -0.0 0.0 -0.15 0.0 -0.3"/>
              </body>
            </body>
          </body>
        </body>
      </body>
      <body name="leg_right_1_link" pos="-0.0150026 -0.08 -0.0585">
        <inertial pos="0.049454 3.7e-05 -0.064102" quat="0.990838 -0.0490292 0.125655 -0.0069297" mass="2.77998" diaginertia="0.00819049 0.0061391 0.00582141"/>
        <joint name="leg_right_1_joint" range="-0.698132 0.261799" />
        <geom class="visual" mesh="leg_right_1_link" />
        <geom name="leg_right1_1_collision" size="0.04" fromto="0.07 0.035 -0.03   0.07 0.035 -0.015" class="collision"/>
        <body name="leg_right_2_link" pos="0.015024 0 -0.1175">
          <inertial pos="-0.005796 2.1e-05 -0.00014" quat="0.5 0.5 0.5 0.5" mass="0.104156" diaginertia="9.9e-05 9.6e-05 8e-06"/>
          <joint name="leg_right_2_joint" axis="0 1 0" range="-0.741765 0.663225" />
          <geom class="visual" mesh="leg_right_2_link" />
          <body name="leg_right_3_link">
            <inertial pos="-0.046481 -0.055912 -0.037141" quat="0.287276 0.626857 -0.260806 0.675651" mass="3.70086" diaginertia="0.0218072 0.0171419 0.0109889"/>
            <joint name="leg_right_3_joint" axis="1 0 0" range="-0.471239 0.471239" />
            <geom class="visual" mesh="leg_right_3_link" />
            <body name="leg_right_length_link" pos="0 -0.0669 -0.09" quat="0 0 1 0">
              <inertial mass="0.1" pos="0 0 0" diaginertia="8.58333e-05 8.58333e-05 5e-06" />
              <joint name="leg_right_length_joint" type="slide" range="0.131973 0.714166" />
              <geom size="5e-05 0.291097" pos="0 0 -0.291097" type="cylinder" class="visual" />
              <body name="leg_right_4_link" quat="-0.173648 0 0.984808 0">
                <inertial pos="-0.007727 0 0" quat="0 0.707107 0 0.707107" mass="0.086323" diaginertia="3.7e-05 3.5e-05 6e-06"/>
                <joint name="leg_right_4_joint" axis="0 1 0" range="-0.741765 0.663225" />
                <geom quat="0.984808 0 -0.173648 0" class="visual" mesh="leg_6_link" />
                <body name="leg_right_5_link">
                  <inertial pos="0.00560127 -5.98529e-06 -0.0297244" quat="-8.95501e-06 0.58162 -1.58775e-05 0.813461" mass="0.61563" diaginertia="0.0019868 0.00170803 0.000338695" />
                  <joint name="leg_right_5_joint" axis="-1 0 0" range="-0.471239 0.471239" />
                  <geom class="visual" mesh="leg_7_link" />
                  <site name="right_foot" pos="0.0575 0 -0.0243" size="0.015"/>
                  <body name="leg_right_foot_link" pos="0 0 -0.034" quat="0.9848078 0 -0.1736482 0">
                    <geom name="right_foot0_collision"  class="foot_capsule" fromto="-0.0830 -0.035 0 0.110 -0.0330 0"/>
                    <geom name="right_foot2_collision"  class="foot_capsule" fromto="-0.0975 -0.021 0 0.120 -0.0215 0"/>
                    <geom name="right_foot4_collision"  class="foot_capsule" fromto="-0.0985 -0.007 0 0.122 -0.0065 0"/>
                    <geom name="right_foot6_collision"  class="foot_capsule" fromto="-0.0985  0.007 0 0.122  0.0065 0"/>
                    <geom name="right_foot8_collision"  class="foot_capsule" fromto="-0.0975  0.021 0 0.120  0.0215 0"/>
                    <geom name="right_foot10_collision" class="foot_capsule" fromto="-0.0830  0.035 0 0.110  0.0330 0"/>
                    <body name="leg_right_ankle_link">
                      <geom name="leg_right_ankle_collision" class="collision" size="0.03" fromto="-0.04 0.0 0.03 0.02 0.0 0.03"/>
                      <geom name="leg_right_ankle_bar_collision" class="collision" size="0.03" fromto="-0.045 -0.035 0.05 -0.045 0.035 0.05"/>
                    </body> 
                  </body>                
                </body>
              </body>
            </body>
            <body name="leg_right_femur_link" pos="0 -0.0669 -0.09" quat="0.819152 0 -0.573576 0">
              <inertial pos="0.055663 0.001808 -0.149159" quat="0.727287 0.0853086 0.0939168 0.674504" mass="4.92196" diaginertia="0.119103 0.117315 0.00884397"/>
              <joint name="leg_right_femur_joint" axis="0 1 0" range="0.174533 1.22173" />
              <geom class="visual" mesh="leg_femur_link" />
              <geom name="leg_right_femur_collision" size="0.0910718 0.20" pos="0.043456 0.000622273 -0.115825" quat="0.194464 0.00344037 0.980904 2.41185e-06" class="collision"/>
              <body name="leg_right_knee_link" pos="0.129945 0 -0.357092" quat="0.34202 0 0.939693 0">
                <inertial pos="-0.038219 -4.9e-05 -0.125673" quat="0.697566 -0.156834 -0.161666 0.680197" mass="0.915324" diaginertia="0.0146275 0.0139478 0.0013687"/>
                <joint name="leg_right_knee_joint" axis="0 -1 0" range="0.349066 2.44346" />
                <geom class="visual" mesh="leg_tibia_link" />
                <geom name="leg_right_knee_collision" size="0.04" fromto="-0.1483 0.0 -0.3 0.0571 0.0 -0.0033" class="collision"/>
                <geom name="leg_right_knee_bar_collision" class="collision" size="0.05" fromto="-0.05 -0.0 0.0 -0.15 0.0 -0.3"/>
              </body>
            </body>
          </body>
        </body>
      </body>
    </body>
  </worldbody>

  <equality>
      <connect anchor="0.0 0.0 0.0" body1="leg_left_4_link" body2="leg_left_knee_link" name="leg_left_closed_kin_joint" solref="0.004 1" />
      <connect anchor="0.0 0.0 0.0" body1="leg_right_4_link" body2="leg_right_knee_link" name="leg_right_closed_kin_joint" solref="0.004 1" />
  </equality>

  <contact>
    <!-- Left leg closed chain -->
    <exclude body1="leg_left_1_link" body2="leg_left_femur_link"/>
    <exclude body1="leg_left_ankle_link" body2="leg_left_knee_link"/>
    
    <!-- Right leg closed chain -->
    <exclude body1="leg_right_1_link" body2="leg_right_femur_link"/>
    <exclude body1="leg_right_ankle_link" body2="leg_right_knee_link"/>
  </contact>
  
  <sensor>
    <gyro           name="imu_ang_vel" site="imu"/>
    <velocimeter    name="imu_lin_vel" site="imu"/>
    <accelerometer  name="imu_lin_acc" site="imu"/>
    <subtreeangmom  name="root_angmom" body="base_link"/>
    <framequat      name="imu_quat" objtype="site" objname="imu"/>
  </sensor>
</mujoco>
